I0720 06:42:30.983823 47959464233088 run_docker.py:118] Mounting /share/apps/alphfold/alphafold -> /mnt/fasta_path_0
I0720 06:42:30.984128 47959464233088 run_docker.py:118] Mounting /public/database/PRODB/uniref90 -> /mnt/uniref90_database_path
I0720 06:42:30.984220 47959464233088 run_docker.py:118] Mounting /public/database/PRODB/mgnify -> /mnt/mgnify_database_path
I0720 06:42:30.984300 47959464233088 run_docker.py:118] Mounting /public/database/PRODB/uniclust30/uniclust30_2018_08 -> /mnt/uniclust30_database_path
I0720 06:42:30.984375 47959464233088 run_docker.py:118] Mounting /public/database/PRODB/bfd -> /mnt/bfd_database_path
I0720 06:42:30.984449 47959464233088 run_docker.py:118] Mounting /public/database/PRODB/pdb70 -> /mnt/pdb70_database_path
I0720 06:42:30.984520 47959464233088 run_docker.py:118] Mounting /public/database -> /mnt/data_dir
I0720 06:42:30.984592 47959464233088 run_docker.py:118] Mounting /public/database/PRODB/pdb_mmcif -> /mnt/template_mmcif_dir
I0720 06:42:30.984662 47959464233088 run_docker.py:118] Mounting /public/database/PRODB/pdb_mmcif -> /mnt/obsolete_pdbs_path
Traceback (most recent call last):
  File "/share/apps/anaconda3/envs/alphafold/lib/python3.9/site-packages/urllib3/connectionpool.py", line 699, in urlopen
    httplib_response = self._make_request(
  File "/share/apps/anaconda3/envs/alphafold/lib/python3.9/site-packages/urllib3/connectionpool.py", line 394, in _make_request
    conn.request(method, url, **httplib_request_kw)
  File "/share/apps/anaconda3/envs/alphafold/lib/python3.9/http/client.py", line 1253, in request
    self._send_request(method, url, body, headers, encode_chunked)
  File "/share/apps/anaconda3/envs/alphafold/lib/python3.9/http/client.py", line 1299, in _send_request
    self.endheaders(body, encode_chunked=encode_chunked)
  File "/share/apps/anaconda3/envs/alphafold/lib/python3.9/http/client.py", line 1248, in endheaders
    self._send_output(message_body, encode_chunked=encode_chunked)
  File "/share/apps/anaconda3/envs/alphafold/lib/python3.9/http/client.py", line 1008, in _send_output
    self.send(msg)
  File "/share/apps/anaconda3/envs/alphafold/lib/python3.9/http/client.py", line 948, in send
    self.connect()
  File "/share/apps/anaconda3/envs/alphafold/lib/python3.9/site-packages/docker/transport/unixconn.py", line 43, in connect
    sock.connect(self.unix_socket)
FileNotFoundError: [Errno 2] No such file or directory

During handling of the above exception, another exception occurred:

Traceback (most recent call last):
  File "/share/apps/anaconda3/envs/alphafold/lib/python3.9/site-packages/requests/adapters.py", line 439, in send
    resp = conn.urlopen(
  File "/share/apps/anaconda3/envs/alphafold/lib/python3.9/site-packages/urllib3/connectionpool.py", line 755, in urlopen
    retries = retries.increment(
  File "/share/apps/anaconda3/envs/alphafold/lib/python3.9/site-packages/urllib3/util/retry.py", line 532, in increment
    raise six.reraise(type(error), error, _stacktrace)
  File "/share/apps/anaconda3/envs/alphafold/lib/python3.9/site-packages/urllib3/packages/six.py", line 769, in reraise
    raise value.with_traceback(tb)
  File "/share/apps/anaconda3/envs/alphafold/lib/python3.9/site-packages/urllib3/connectionpool.py", line 699, in urlopen
    httplib_response = self._make_request(
  File "/share/apps/anaconda3/envs/alphafold/lib/python3.9/site-packages/urllib3/connectionpool.py", line 394, in _make_request
    conn.request(method, url, **httplib_request_kw)
  File "/share/apps/anaconda3/envs/alphafold/lib/python3.9/http/client.py", line 1253, in request
    self._send_request(method, url, body, headers, encode_chunked)
  File "/share/apps/anaconda3/envs/alphafold/lib/python3.9/http/client.py", line 1299, in _send_request
    self.endheaders(body, encode_chunked=encode_chunked)
  File "/share/apps/anaconda3/envs/alphafold/lib/python3.9/http/client.py", line 1248, in endheaders
    self._send_output(message_body, encode_chunked=encode_chunked)
  File "/share/apps/anaconda3/envs/alphafold/lib/python3.9/http/client.py", line 1008, in _send_output
    self.send(msg)
  File "/share/apps/anaconda3/envs/alphafold/lib/python3.9/http/client.py", line 948, in send
    self.connect()
  File "/share/apps/anaconda3/envs/alphafold/lib/python3.9/site-packages/docker/transport/unixconn.py", line 43, in connect
    sock.connect(self.unix_socket)
urllib3.exceptions.ProtocolError: ('Connection aborted.', FileNotFoundError(2, 'No such file or directory'))

During handling of the above exception, another exception occurred:

Traceback (most recent call last):
  File "/share/apps/anaconda3/envs/alphafold/lib/python3.9/site-packages/docker/api/client.py", line 214, in _retrieve_server_version
    return self.version(api_version=False)["ApiVersion"]
  File "/share/apps/anaconda3/envs/alphafold/lib/python3.9/site-packages/docker/api/daemon.py", line 181, in version
    return self._result(self._get(url), json=True)
  File "/share/apps/anaconda3/envs/alphafold/lib/python3.9/site-packages/docker/utils/decorators.py", line 46, in inner
    return f(self, *args, **kwargs)
  File "/share/apps/anaconda3/envs/alphafold/lib/python3.9/site-packages/docker/api/client.py", line 237, in _get
    return self.get(url, **self._set_request_timeout(kwargs))
  File "/share/apps/anaconda3/envs/alphafold/lib/python3.9/site-packages/requests/sessions.py", line 555, in get
    return self.request('GET', url, **kwargs)
  File "/share/apps/anaconda3/envs/alphafold/lib/python3.9/site-packages/requests/sessions.py", line 542, in request
    resp = self.send(prep, **send_kwargs)
  File "/share/apps/anaconda3/envs/alphafold/lib/python3.9/site-packages/requests/sessions.py", line 655, in send
    r = adapter.send(request, **kwargs)
  File "/share/apps/anaconda3/envs/alphafold/lib/python3.9/site-packages/requests/adapters.py", line 498, in send
    raise ConnectionError(err, request=request)
requests.exceptions.ConnectionError: ('Connection aborted.', FileNotFoundError(2, 'No such file or directory'))

During handling of the above exception, another exception occurred:

Traceback (most recent call last):
  File "/share/apps/alphfold/alphafold/docker/run_docker.py", line 192, in <module>
    app.run(main)
  File "/share/apps/anaconda3/envs/alphafold/lib/python3.9/site-packages/absl/app.py", line 312, in run
    _run_main(main, args)
  File "/share/apps/anaconda3/envs/alphafold/lib/python3.9/site-packages/absl/app.py", line 258, in _run_main
    sys.exit(main(argv))
  File "/share/apps/alphfold/alphafold/docker/run_docker.py", line 163, in main
    client = docker.from_env()
  File "/share/apps/anaconda3/envs/alphafold/lib/python3.9/site-packages/docker/client.py", line 96, in from_env
    return cls(
  File "/share/apps/anaconda3/envs/alphafold/lib/python3.9/site-packages/docker/client.py", line 45, in __init__
    self.api = APIClient(*args, **kwargs)
  File "/share/apps/anaconda3/envs/alphafold/lib/python3.9/site-packages/docker/api/client.py", line 197, in __init__
    self._version = self._retrieve_server_version()
  File "/share/apps/anaconda3/envs/alphafold/lib/python3.9/site-packages/docker/api/client.py", line 221, in _retrieve_server_version
    raise DockerException(
docker.errors.DockerException: Error while fetching server API version: ('Connection aborted.', FileNotFoundError(2, 'No such file or directory'))
